<?xml version="1.0" ?>

<robot name="BhimBot_five_dof_arm" xmlns:xacro="http://www.ros.org/wiki/xacro">

<!-- Include materials-->
  <material name="Black">
    <color rgba="0.0 0.0 0.0 1.0" />
  </material>

  <material name="Red">
    <color rgba="0.8 0.0 0.0 1.0" />
  </material>

  <material name="White">
    <color rgba="1.0 1.0 1.0 1.0" />
  </material>

  <material name="Blue">
    <color rgba="0.0 0.0 1.0 1.0"/>
  </material>

  <material name="Grey">
    <color rgba="0.5 0.5 0.5 1.0" />
  </material>

<property name="M_PI" value="3.14159" />

<property name="base_width" value="0.08" />
<property name="base_len" value="0.06" />

<property name="shoulder_pan_width" value="0.08" />
<property name="shoulder_pan_len" value="0.02" />

<property name="shoulder_pitch_len" value="0.14" />
<property name="shoulder_pitch_width" value="0.04" />
<property name="shoulder_pitch_height" value="0.04" />

<property name="elbow_pitch_len" value="0.22" />
<property name="elbow_pitch_width" value="0.04" />
<property name="elbow_pitch_height" value="0.04" />

<property name="wrist_roll_width" value="0.06" />
<property name="wrist_roll_len" value="0.02" />
<!-- //////////////////////////////////////////////////////////////////////////////////////////////////////////////////////  -->

  <link name="bottom_link">
    <visual>
      <origin xyz="0 0 -0.04" rpy="0 0 0" />
      <geometry>
        <box size="1 1 0.02" />
      </geometry>
      <material name="White" />
    </visual>
  </link>

  <joint name="bottom_joint" type="fixed">
    <parent link="base_link" />
    <child link="bottom_link" />
    <origin xyz="0 0 0" rpy="0 0 0" />
  </joint>

  <link name="base_link">
    <visual>
      <origin xyz="0 0 0" rpy="0 0 0" />
      <geometry>
        <cylinder radius="${base_width}" length="${base_len}" />
      </geometry>
      <material name="Blue" />
    </visual>
  </link>

  <joint name="shoulder_pan_joint" type="revolute">
    <parent link="base_link" />
    <child link="shoulder_pan_link" />
    <origin xyz="0 0 0.04" rpy="-${M_PI/2} ${M_PI/2} ${M_PI*0}" />
    <axis xyz="-1 0 0" />
    <limit effort="300" velocity="1" lower="-1.57" upper="1.57" />
  </joint>

  <link name="shoulder_pan_link">
    <visual>
      <origin xyz="0 0 0" rpy="0 ${M_PI/2} 0" />
      <geometry>
        <cylinder radius="${shoulder_pan_width}" length="${shoulder_pan_len}" />
      </geometry>
      <material name="Grey" />
    </visual>
  </link>
 
  <joint name="shoulder_pitch_joint" type="revolute">
    <parent link="shoulder_pan_link" />
    <child link="shoulder_pitch_link" />
    <origin xyz="-0.041 0.0021 0.0" rpy="-${M_PI/2} 0 ${M_PI/2}" />
    <axis xyz="0 1 0" />
    <limit effort="300" velocity="1" lower="-1.57" upper="1.57" />
  </joint>

  <link name="shoulder_pitch_link">
    <visual> 
      <origin xyz="-0.002 0 0.04" rpy="0 ${M_PI/2} 0" />
      <geometry>
        <box size="${shoulder_pitch_len} ${shoulder_pitch_width} ${shoulder_pitch_height}" />
      </geometry>
      <material name="Blue" />
    </visual>
  </link>

  <joint name="elbow_pitch_joint" type="revolute">
    <parent link="shoulder_pitch_link" />
    <child link="elbow_pitch_link" />
    <origin xyz="0 0 0.11" rpy="0 0 ${M_PI/2}" />
    <axis xyz="1 0 0" />
    <limit effort="300" velocity="1" lower="-1.57" upper="1.57" />
  </joint>
  
  <link name="elbow_pitch_link">
    <visual>
      <origin xyz="0 0 0.11" rpy="0 ${M_PI/2} 0" />
      <geometry>
        <box size="${elbow_pitch_len} ${elbow_pitch_width} ${elbow_pitch_height}" />
      </geometry>
      <material name="White" />
    </visual>
  </link>

  <joint name="wrist_roll_joint" type="revolute">
    <parent link="elbow_pitch_link" />
    <child link="wrist_roll_link"/>
    <origin xyz="0 0 0.22" rpy="-${M_PI/2} ${M_PI/2} 0" />
    <axis xyz="-1 0 0" />
    <limit effort="300" velocity="1" lower="-1.57" upper="1.57" />
  </joint>

  <link name="wrist_roll_link">
    <visual>
      <origin xyz="0 0 0" rpy="0 ${M_PI/2} 0"/>
      <geometry>
        <cylinder radius="${wrist_roll_width}" length="${wrist_roll_len}" />
      </geometry>
      <material name="Grey" />
    </visual>
  </link>
</robot>
